Workbook

Sheet SCALING SUMMARY
A1: INTEGRATED NBC 105:2025 + RESPONSE SPECTRUM SCALING
A2: No intermediate scaling workbook is required. Values below were calculated and applied in the same ETABS session.
A4: Source EDB | B4: D:\Thesis\Etabs\NBC Ultimate\Ultimate Belt truss, outrigger and cap truss 6 m\ULTIMATE LOAD - NEPAL - 3 - BELT TRUSS, OUTRIGGER CAP TRUSS.EDB
A6: Direction | B6: RS Case | C6: RS Base Shear | D6: Existing ETABS SF | E6: Target Base Shear | F6: Target Case | G6: Calculated SF Multiplier | H6: NEW ETABS SF | I6: Verified RS Base Shear | J6: Verification Ratio
A7: X | B7: RSX P Delta | C7: 22679.002 | D7: 0.7757576 | E7: 24144.086 | F7: EQX+ P-Delta | G7: 1.0646009 | H7: 0.82587225 | I7: 24144.086 | J7: 1
A8: Y | B8: RSY P Delta | C8: 24156.11 | D8: 1.0525596 | E8: 25608.705 | F8: EQY+ P-Delta | G8: 1.0601337 | H8: 1.1158538 | I8: 25608.705 | J8: 1
A12: NBC 105:2025 RESULTS
A13: Direction | B13: Aw (m²) | C13: Adopted T1 (s) | D13: Ch(T1) | E13: C(T1) | F13: Cd Ultimate | G13: Cd Service | H13: k
A14: X | B14: 1.9582936 | C14: 2.0385674 | D14: 1.2263514 | E14: 0.429223 | F14: 0.08759653 | G14: 0.071537166 | H14: 1.7692837
A15: Y | B15: 2.2030803 | C15: 1.9219798 | D15: 1.3007421 | E15: 0.45525973 | F15: 0.09291015 | G15: 0.075876622 | H15: 1.7109899
A17: Scaling rule | B17: Multiplier = Governing P-Delta Base Shear / RS Base Shear
A18: 2 | B18: NEW ETABS SF = Existing ETABS SF × Multiplier

Sheet HOME
A1: NBC 105:2025 — SEISMIC CALCULATOR
A2: Navigation dashboard — enter data in NBC Calculator, review results, then use ETABS INPUT for EQX/EQY C and k.
A4: NBC CALCULATOR | E4: ETABS INPUT
A6: Main inputs, individual bay/wall Aw calculation, T1 and seismic coefficients | E6: Clean C and k values for EQX/EQY — ready to enter in ETABS
A7: DEFINITIONS & USE | E7: VERIFICATION
A9: Equations, workflow and meaning of inputs/outputs | E9: Benchmark checks against the original workbook
A10: NBC PARAMETERS | E10: Ch STATIC
A12: NBC 105:2025 structural-system Rμ / Ωu / Ωs table | E12: Static Ch(T) source spectrum
A13: Ch MODAL X | E13: Ch MODAL Y
A15: Modal X Ch(T) source spectrum | E15: Modal Y Ch(T) source spectrum
A17: WORKFLOW
A18: 1. Select structural system and enter building/soil data → 2. Check each bay/wall geometry → 3. Select Static/Modal Ch(T) source → 4. Review Cd and k → 5. Copy C and k from ETABS INPUT into EQX/EQY User Coefficient loading.
A21: Tip: use the sheet tabs only for detailed work; use this page to jump directly to the required section.
A22: Navigation tip: the calculator uses no frozen columns. Use the top navigation bar or sheet tabs; this keeps horizontal and vertical scrolling smooth.

Sheet ETABS MASTER IMPORT
A1: ETABS → EXCEL MASTER GEOMETRY IMPORT
A2: This sheet is populated by the Python program from the active ETABS model before NBC calculation.
A3: ETABS geometry is the master source. Wall thickness and wall length are written in mm; story height/count are written to NBC Calculator.
A5: Direction | B5: Stories | C5: Wall No. | D5: Section | E5: Wall L (mm) | F5: Grid spacing (m) | G5: Thickness (mm) | H5: Opening W (mm) | I5: Opening H (mm) | J5: No. Openings | K5: X | L5: Y | M5: Z | N5: No. Stories | O5: Source Areas | P5: Pier Assignment | Q5: Spandrel Assignment | R5: Opening Detection
A6: X | B6: Story1, Story10, Story11, Story12, Story13, Story14, Story15, Story16, Story17, Story18, Story19, Story2, Story20, Story21, Story22, Story23, Story24, Story25, Story3, Story4, Story5, Story6, Story7, Story8, Story9 | C6: 1 | D6: Wall 600 | E6: 6000 | F6: 6 | G6: 600 | H6: 2000 | I6: 0 | J6: 1 | K6: 6 | L6: 9 | M6: 55.1 | N6: 25 | O6: 1, 2, 3, 4, 5, 6, 7, 8, 9, 10, 11, 12, 13, 14, 229, 230, 231, 232, 233, 234, 235, 236, 237, 238, 239 | P6: P1 | Q6: None | R6: ETABS spandrel opening; X physical bay
A7: X | B7: Story1, Story10, Story11, Story12, Story13, Story14, Story15, Story16, Story17, Story18, Story19, Story2, Story20, Story21, Story22, Story23, Story24, Story25, Story3, Story4, Story5, Story6, Story7, Story8, Story9 | C7: 1 | D7: Wall 600 | E7: 6000 | F7: 6 | G7: 600 | H7: 2000 | I7: 0 | J7: 1 | K7: 6 | L7: 9 | M7: 55.1 | N7: 25 | O7: 1, 2, 3, 4, 5, 6, 7, 8, 9, 10, 11, 12, 13, 14, 229, 230, 231, 232, 233, 234, 235, 236, 237, 238, 239 | P7: P1 | Q7: None | R7: ETABS spandrel opening; X physical bay
A8: X | B8: Story1, Story10, Story11, Story12, Story13, Story14, Story15, Story16, Story17, Story18, Story19, Story2, Story20, Story21, Story22, Story23, Story24, Story25, Story3, Story4, Story5, Story6, Story7, Story8, Story9 | C8: 15 | D8: Wall 600 | E8: 6000 | F8: 6 | G8: 600 | H8: 2000 | I8: 0 | J8: 1 | K8: 18 | L8: 9 | M8: 55.1 | N8: 25 | O8: 15, 16, 17, 18, 19, 20, 21, 22, 23, 24, 25, 26, 27, 28, 290, 291, 292, 293, 294, 295, 296, 297, 298, 299, 300 | P8: P3 | Q8: None | R8: ETABS spandrel opening; X physical bay
A9: X | B9: Story1, Story10, Story11, Story12, Story13, Story14, Story15, Story16, Story17, Story18, Story19, Story2, Story20, Story21, Story22, Story23, Story24, Story25, Story3, Story4, Story5, Story6, Story7, Story8, Story9 | C9: 15 | D9: Wall 600 | E9: 6000 | F9: 6 | G9: 600 | H9: 2000 | I9: 0 | J9: 1 | K9: 18 | L9: 9 | M9: 55.1 | N9: 25 | O9: 15, 16, 17, 18, 19, 20, 21, 22, 23, 24, 25, 26, 27, 28, 290, 291, 292, 293, 294, 295, 296, 297, 298, 299, 300 | P9: P3 | Q9: None | R9: ETABS spandrel opening; X physical bay
A10: Y | B10: Story1, Story10, Story11, Story12, Story13, Story14, Story15, Story16, Story17, Story18, Story19, Story2, Story20, Story21, Story22, Story23, Story24, Story25, Story3, Story4, Story5, Story6, Story7, Story8, Story9 | C10: 354 | D10: Wall 600 | E10: 6000 | F10: 6 | G10: 600 | H10: 0 | I10: 0 | J10: 0 | K10: 7 | L10: 9 | M10: 1.9 | N10: 25 | O10: 354, 355, 356, 357, 358, 359, 360, 361, 362, 363, 364, 365, 366, 367, 368, 369, 370, 371, 372, 373, 374, 375, 376, 377, 378, 482, 484, 485, 486, 487, 488, 489, 490, 491, 492, 493, 494, 495, 496, 497, 498, 499, 500, 501, 502, 503, 504, 505, 506, 507 | P10: P1 | Q10: None, None | R10: Physical wall length follows wall direction: X-wall uses X-grid spacing; Y-wall uses Y-grid spacing; grouped by ETABS Pier
A11: Y | B11: Story1, Story10, Story11, Story12, Story13, Story14, Story15, Story16, Story17, Story18, Story19, Story2, Story20, Story21, Story22, Story23, Story24, Story25, Story3, Story4, Story5, Story6, Story7, Story8, Story9 | C11: 353 | D11: Wall 600 | E11: 6000 | F11: 6 | G11: 600 | H11: 0 | I11: 0 | J11: 0 | K11: 12 | L11: 9 | M11: 1.9 | N11: 25 | O11: 353, 380, 381, 382, 383, 384, 385, 386, 387, 388, 389, 390, 391, 392, 393, 394, 395, 396, 397, 398, 399, 400, 401, 402, 403, 405, 406, 407, 408, 409, 410, 411, 412, 413, 414, 415, 416, 417, 418, 419, 420, 421, 422, 423, 424, 425, 426, 427, 428, 429, 481, 508, 509, 510, 511, 512, 513, 514, 515, 516, 517, 518, 519, 520, 521, 522, 523, 524, 525, 526, 527, 528, 529, 530, 531, 532, 533, 534, 535, 536, 537, 538, 539, 540, 541, 542, 543, 544, 545, 546, 547, 548, 549, 550, 551, 552, 553, 554, 555, 556 | P11: P2 | Q11: None, None, None, None | R11: Physical wall length follows wall direction: X-wall uses X-grid spacing; Y-wall uses Y-grid spacing; grouped by ETABS Pier
A12: Y | B12: Story1, Story10, Story11, Story12, Story13, Story14, Story15, Story16, Story17, Story18, Story19, Story2, Story20, Story21, Story22, Story23, Story24, Story25, Story3, Story4, Story5, Story6, Story7, Story8, Story9 | C12: 476 | D12: Wall 600 | E12: 6000 | F12: 6 | G12: 600 | H12: 0 | I12: 0 | J12: 0 | K12: 17 | L12: 9 | M12: 1.9 | N12: 25 | O12: 476, 430, 431, 432, 433, 434, 435, 436, 437, 438, 439, 440, 441, 442, 443, 444, 445, 446, 447, 448, 449, 475, 477, 478, 479, 483, 557, 558, 559, 560, 561, 562, 563, 564, 565, 566, 567, 568, 569, 570, 571, 572, 598, 599, 600, 601, 602, 603, 604, 605 | P12: P3 | Q12: None, None | R12: Physical wall length follows wall direction: X-wall uses X-grid spacing; Y-wall uses Y-grid spacing; grouped by ETABS Pier

Sheet ETABS INPUT
A1: ETABS INPUT — USER COEFFICIENT C & k
A2: Select ULTIMATE or SERVICE independently for EQX and EQY. The selected C is linked automatically from the NBC Calculator; k is the calculated building-height exponent.
A4: HOME | B4: NBC CALCULATOR | C4: DEFINITIONS | D4: VERIFICATION
A6: ETABS Load Pattern | B6: DESIGN CONDITION | C6: C — SELECTED Cd(T1) | D6: k — HEIGHT EXPONENT | E6: Ch(T) SOURCE | F6: STATUS
A7: EQX | B7: Ultimate | C7: =IF(B7="Ultimate",'NBC Calculator'!N17,'NBC Calculator'!N19) | D7: ='NBC Calculator'!N20 | E7: ='NBC Calculator'!N22 | F7: READY
A8: EQY | B8: Ultimate | C8: =IF(B8="Ultimate",'NBC Calculator'!R17,'NBC Calculator'!R19) | D8: ='NBC Calculator'!R20 | E8: ='NBC Calculator'!R22 | F8: READY
A10: COPY TO ETABS — SELECTED CONDITION
A11: Pattern | B11: Condition | C11: C | D11: k | E11: Meaning
A12: =A7 | B12: =B7 | C12: =C7 | D12: =D7 | E12: C = selected Cd(T1); k = height exponent
A13: =A8 | B13: =B8 | C13: =C8 | D13: =D8 | E13: C = selected Cd(T1); k = height exponent
A16: NBC 105:2025 — ULTIMATE AND SERVICE VALUES
A17: Direction | B17: Ultimate Cd(T1) | C17: Service Cd(T1) | D17: Selected | E17: Selected C | F17: k
A18: EQX | B18: ='NBC Calculator'!N17 | C18: ='NBC Calculator'!N19 | D18: =B7 | E18: =C7 | F18: =D7
A19: EQY | B19: ='NBC Calculator'!R17 | C19: ='NBC Calculator'!R19 | D19: =B8 | E19: =C8 | F19: =D8
A21: Important: ETABS is NOT restricted to Ultimate. Select Ultimate for ULS design or Service for the corresponding serviceability/design situation. The selected C is the value to enter for that load pattern.

Sheet NBC Calculator
A1: NBC 105:2025 — Interactive Shear-Wall Seismic Coefficient Calculator
A2: ETABS is the MASTER geometry source | Python syncs ETABS → Excel → NBC calculation → ETABS | N2: Ch(T) source — X | R2: Ch(T) source — Y
A3: HOME | B3: ETABS INPUT | C3: DEFINITIONS | D3: VERIFICATION | E3: NBC PARAMETERS | F3: Ch STATIC | G3: Ch MODAL X | H3: Ch MODAL Y | M3: Ch(T) source — X | N3: Modal X | Q3: Ch(T) source — Y | R3: Modal Y
A4: GENERAL INPUTS | D4: X-DIRECTION — INITIAL GEOMETRY | G4: Y-DIRECTION — INITIAL GEOMETRY | M4: X-DIRECTION RESULTS / EQX | Q4: Y-DIRECTION RESULTS / EQY | U4: HOME
A5: Number of storeys — FROM ETABS | B5: 25 | D5: Grid spacing X (m) | E5: 6 | G5: Grid spacing Y (m) | H5: 6 | M5: Aw (m²) | N5: =$N$28 | Q5: Aw (m²) | R5: =$N$35
A6: Average storey height (m) — FROM ETABS | B6: 3.8 | D6: Wall thickness X (mm) — FROM ETABS | E6: 600 | G6: Wall thickness Y (mm) — FROM ETABS | H6: 600 | M6: kt = 0.075/√Aw | N6: =0.075/SQRT(N5) | Q6: kt = 0.075/√Aw | R6: =0.075/SQRT(R5)
A7: Basement storeys excluded from H | B7: 0 | D7: Opening width X (mm) — FROM ETABS | E7: 2000 | G7: Opening width Y (mm) — FROM ETABS | H7: 0 | M7: Empirical T1 (s) | N7: =N6*$B$8^0.75 | Q7: Empirical T1 (s) | R7: =R6*$B$8^0.75
A8: Effective building height H (m) | B8: =MAX(0,(B5-B7)*B6) | D8: Opening height X (mm) | E8: 0 | G8: Opening height Y (mm) | H8: 0 | M8: Amplified empirical T1 (s) | N8: =N7*$B$15 | Q8: Amplified empirical T1 (s) | R8: =R7*$B$15
A9: Soil type | B9: C | E9: 0 | H9: 0 | M9: Adopted T1 (s) | N9: =IF($B$16="",N8,MIN(N8,$B$16)) | Q9: Adopted T1 (s) | R9: =IF($B$17="",R8,MIN(R8,$B$17))
A10: Seismic zone factor Z | B10: 0.35 | D10: Structural system | E10: RC Shear wall — Dual System | G10: Grid 1 wall lines | H10: 3 | M10: Ch(T1) — direct interpolation | N10: =IF($N$3="Static",INDEX('Ch Static'!$B$4:$E$12004,MATCH(N9,'Ch Static'!$A$4:$A$12004,1),MATCH("Soil "&$B$9,'Ch Static'!$B$3:$E$3,0))+(N9-O10)*(INDEX('Ch Static'!$B$4:$E$12004,MATCH(N9,'Ch Static'!$A$4:$A$12004,1)+1,MATCH("Soil "&$B$9,'Ch Static'!$B$3:$E$3,0))-INDEX('Ch Static'!$B$4:$E$12004,MATCH(N9,'Ch Static'!$A$4:$A$12004,1),MATCH("Soil "&$B$9,'Ch Static'!$B$3:$E$3,0)))/(P10-O10),INDEX('Ch Modal X'!$B$4:$E$12004,MATCH(N9,'Ch Modal X'!$A$4:$A$12004,1),MATCH("Soil "&$B$9,'Ch Modal X'!$B$3:$E$3,0))+(N9-O10)*(INDEX('Ch Modal X'!$B$4:$E$12004,MATCH(N9,'Ch Modal X'!$A$4:$A$12004,1)+1,MATCH("Soil "&$B$9,'Ch Modal X'!$B$3:$E$3,0))-INDEX('Ch Modal X'!$B$4:$E$12004,MATCH(N9,'Ch Modal X'!$A$4:$A$12004,1),MATCH("Soil "&$B$9,'Ch Modal X'!$B$3:$E$3,0)))/(P10-O10)) | O10: =IF($N$3="Static",INDEX('Ch Static'!$A$4:$A$12004,MATCH(N9,'Ch Static'!$A$4:$A$12004,1)),INDEX('Ch Modal X'!$A$4:$A$12004,MATCH(N9,'Ch Modal X'!$A$4:$A$12004,1))) | P10: =IF($N$3="Static",INDEX('Ch Static'!$A$4:$A$12004,MATCH(N9,'Ch Static'!$A$4:$A$12004,1)+1),INDEX('Ch Modal X'!$A$4:$A$12004,MATCH(N9,'Ch Modal X'!$A$4:$A$12004,1)+1)) | Q10: Ch(T1) — direct interpolation | R10: =IF($R$3="Static",INDEX('Ch Static'!$B$4:$E$12004,MATCH(R9,'Ch Static'!$A$4:$A$12004,1),MATCH("Soil "&$B$9,'Ch Static'!$B$3:$E$3,0))+(R9-S10)*(INDEX('Ch Static'!$B$4:$E$12004,MATCH(R9,'Ch Static'!$A$4:$A$12004,1)+1,MATCH("Soil "&$B$9,'Ch Static'!$B$3:$E$3,0))-INDEX('Ch Static'!$B$4:$E$12004,MATCH(R9,'Ch Static'!$A$4:$A$12004,1),MATCH("Soil "&$B$9,'Ch Static'!$B$3:$E$3,0)))/(T10-S10),INDEX('Ch Modal Y'!$B$4:$E$12004,MATCH(R9,'Ch Modal Y'!$A$4:$A$12004,1),MATCH("Soil "&$B$9,'Ch Modal Y'!$B$3:$E$3,0))+(R9-S10)*(INDEX('Ch Modal Y'!$B$4:$E$12004,MATCH(R9,'Ch Modal Y'!$A$4:$A$12004,1)+1,MATCH("Soil "&$B$9,'Ch Modal Y'!$B$3:$E$3,0))-INDEX('Ch Modal Y'!$B$4:$E$12004,MATCH(R9,'Ch Modal Y'!$A$4:$A$12004,1),MATCH("Soil "&$B$9,'Ch Modal Y'!$B$3:$E$3,0)))/(T10-S10)) | S10: =IF($R$3="Static",INDEX('Ch Static'!$A$4:$A$12004,MATCH(R9,'Ch Static'!$A$4:$A$12004,1)),INDEX('Ch Modal Y'!$A$4:$A$12004,MATCH(R9,'Ch Modal Y'!$A$4:$A$12004,1))) | T10: =IF($R$3="Static",INDEX('Ch Static'!$A$4:$A$12004,MATCH(R9,'Ch Static'!$A$4:$A$12004,1)+1),INDEX('Ch Modal Y'!$A$4:$A$12004,MATCH(R9,'Ch Modal Y'!$A$4:$A$12004,1)+1))
A11: Importance factor I | B11: 1 | D11: Grid 2 wall lines | E11: 2 | G11: Grid 2 wall lines | H11: 0 | M11: Z | N11: =$B$10 | Q11: Z | R11: =$B$10
A12: Ductility factor Rμ | B12: =INDEX('NBC Parameters'!$B$16:$B$36,MATCH($E$10,'NBC Parameters'!$A$16:$A$36,0)) | D12: Bays with wall / grid X | E12: 4 | G12: Grid 3 wall lines | H12: 0 | M12: I | N12: =$B$11 | Q12: I | R12: =$B$11
A13: Overstrength Ωu | B13: =INDEX('NBC Parameters'!$C$16:$C$36,MATCH($E$10,'NBC Parameters'!$A$16:$A$36,0)) | D13: Structural system | E13: RC Shear wall — Dual System | G13: Bays with wall / grid Y | H13: 3 | M13: Rμ | N13: =$B$12 | Q13: Rμ | R13: =$B$12
A14: Overstrength Ωs | B14: =INDEX('NBC Parameters'!$D$16:$D$36,MATCH($E$10,'NBC Parameters'!$A$16:$A$36,0)) | M14: Ωu | N14: =$B$13 | Q14: Ωu | R14: =$B$13
A15: Approx. period factor | B15: 1.25 | D15: Structural system | E15: RC Shear wall — Dual System | M15: Ωs | N15: =$B$14 | Q15: Ωs | R15: =$B$14
A16: ETABS/Rayleigh T1-X (s), optional | M16: C(T1)=Ch·Z·I | N16: =N10*N11*N12 | Q16: C(T1)=Ch·Z·I | R16: =R10*R11*R12
A17: ETABS/Rayleigh T1-Y (s), optional | M17: Cd ULS — ULTIMATE (NBC 105:2025 Cl. 6.1.1) | N17: =N16/(N13*N14) | Q17: Cd ULS — ULTIMATE (NBC 105:2025 Cl. 6.1.1) | R17: =R16/(R13*R14)
A18: Seismic weight W (kN), optional | D18: Note | E18: Wall dimensions are entered/read in mm. H and grid dimensions remain in m. If ETABS/Rayleigh T1 is supplied, NBC adopted T1 = lesser of amplified empirical T1 and ETABS T1; otherwise amplified empirical T1 is used. | M18: Cs(T1)=0.20C | N18: =0.2*N16 | Q18: Cs(T1)=0.20C | R18: =0.2*R16
A19: Serviceability Rs | B19: 1 | M19: Cd SLS — SERVICE (NBC 105:2025 Cl. 6.1.2) | N19: =N18/N15 | Q19: Cd SLS — SERVICE (NBC 105:2025 Cl. 6.1.2) | R19: =R18/R15
M20: k exponent | N20: =IF(N9<=0.5,1,IF(N9>=2.5,2,1+(N9-0.5)/2)) | Q20: k exponent | R20: =IF(R9<=0.5,1,IF(R9>=2.5,2,1+(R9-0.5)/2))
M21: Base shear V=Cd·W (kN) | N21: =IF($B$18="",NA(),N17*$B$18) | Q21: Base shear V=Cd·W (kN) | R21: =IF($B$18="",NA(),R17*$B$18)
A22: X-DIRECTION — INDIVIDUAL BAY / WALL Aw CALCULATION | Q22: Ch(T) SOURCE — Y | R22: =IF(R3="Static","STATIC → Ch Static","MODAL Y → Ch Modal Y") | U22: HOME
A23: Direction | B23: Grid No. | C23: Bay No. | D23: Wall No. | E23: Bay length (mm) | F23: Wall L (mm) | G23: t (mm) | H23: Opening W (mm) | I23: Opening H (mm) | J23: No. Openings | K23: Awi (m²) | L23: Lwi/H | M23: 0.2+(Lwi/H)² | N23: Aw contribution
A24: X | B24: B | C24: 1 | D24: 1 | E24: 6000 | F24: 6000 | G24: 600 | H24: 2000 | I24: 0 | J24: 1 | K24: =MAX(0,(F24-J24*H24)/1000*G24/1000) | L24: =IFERROR(MIN((F24/1000)/$B$8,0.9),0) | M24: =0.2+L24^2 | N24: =K24*M24
A25: X | B25: B | C25: 2 | D25: 1 | E25: 6000 | F25: 6000 | G25: 600 | H25: 2000 | I25: 0 | J25: 1 | K25: =MAX(0,(F25-J25*H25)/1000*G25/1000) | L25: =IFERROR(MIN((F25/1000)/$B$8,0.9),0) | M25: =0.2+L25^2 | N25: =K25*M25
A26: X | B26: D | C26: 3 | D26: 15 | E26: 6000 | F26: 6000 | G26: 600 | H26: 2000 | I26: 0 | J26: 1 | K26: =MAX(0,(F26-J26*H26)/1000*G26/1000) | L26: =IFERROR(MIN((F26/1000)/$B$8,0.9),0) | M26: =0.2+L26^2 | N26: =K26*M26
A27: X | B27: D | C27: 4 | D27: 15 | E27: 6000 | F27: 6000 | G27: 600 | H27: 2000 | I27: 0 | J27: 1 | K27: =MAX(0,(F27-J27*H27)/1000*G27/1000) | L27: =IFERROR(MIN((F27/1000)/$B$8,0.9),0) | M27: =0.2+L27^2 | N27: =K27*M27
A28: TOTAL X Aw | K28: =SUM(K24:K27) | N28: =SUM(N24:N27)
Q29: MODAL SPECTRUM — Y DIRECTION
A30: Y-DIRECTION — INDIVIDUAL BAY / WALL Aw CALCULATION | Q30: Adopted T1 (s) | R30: =R9 | U30: HOME
A31: Direction | B31: Grid No. | C31: Bay No. | D31: Wall No. | E31: Bay length (mm) | F31: Wall L (mm) | G31: t (mm) | H31: Opening W (mm) | I31: Opening H (mm) | J31: No. Openings | K31: Awi (m²) | L31: Lwi/H | M31: 0.2+(Lwi/H)² | N31: Aw contribution | Q31: Ch_modal(T1) — direct interpolation | R31: =INDEX('Ch Modal Y'!$B$4:$E$12004,MATCH(R30,'Ch Modal Y'!$A$4:$A$12004,1),MATCH("Soil "&$B$9,'Ch Modal Y'!$B$3:$E$3,0))+(R30-S31)*(INDEX('Ch Modal Y'!$B$4:$E$12004,MATCH(R30,'Ch Modal Y'!$A$4:$A$12004,1)+1,MATCH("Soil "&$B$9,'Ch Modal Y'!$B$3:$E$3,0))-INDEX('Ch Modal Y'!$B$4:$E$12004,MATCH(R30,'Ch Modal Y'!$A$4:$A$12004,1),MATCH("Soil "&$B$9,'Ch Modal Y'!$B$3:$E$3,0)))/(T31-S31) | S31: =INDEX('Ch Modal Y'!$A$4:$A$12004,MATCH(R30,'Ch Modal Y'!$A$4:$A$12004,1)) | T31: =INDEX('Ch Modal Y'!$A$4:$A$12004,MATCH(R30,'Ch Modal Y'!$A$4:$A$12004,1)+1)
A32: Y | B32: 2 | C32: 1 | D32: 354 | E32: 6000 | F32: 6000 | G32: 600 | H32: 0 | I32: 0 | J32: 0 | K32: =MAX(0,(F32-J32*H32)/1000*G32/1000) | L32: =IFERROR(MIN((F32/1000)/$B$8,0.9),0) | M32: =0.2+L32^2 | N32: =K32*M32 | Q32: C_modal(T1)=Ch·Z·I | R32: =R31*$B$10*$B$11
A33: Y | B33: 2 | C33: 2 | D33: 353 | E33: 6000 | F33: 6000 | G33: 600 | H33: 0 | I33: 0 | J33: 0 | K33: =MAX(0,(F33-J33*H33)/1000*G33/1000) | L33: =IFERROR(MIN((F33/1000)/$B$8,0.9),0) | M33: =0.2+L33^2 | N33: =K33*M33 | Q33: Cd_modal ULS | R33: =R32/($B$12*$B$13)
A34: Y | B34: 2 | C34: 3 | D34: 476 | E34: 6000 | F34: 6000 | G34: 600 | H34: 0 | I34: 0 | J34: 0 | K34: =MAX(0,(F34-J34*H34)/1000*G34/1000) | L34: =IFERROR(MIN((F34/1000)/$B$8,0.9),0) | M34: =0.2+L34^2 | N34: =K34*M34 | Q34: k exponent | R34: =R20
A35: TOTAL Y Aw | K35: =SUM(K32:K34) | N35: =SUM(N32:N34) | Q35: Selected Y source | R35: =R3
Q36: Static source | R36: Ch Static
Q37: Modal source | R37: Ch Modal Y
A38: INPUT STRUCTURE
A39: Each physical wall/bay is a separate record. Grid number, bay number, wall number, wall length, opening width/height and number of openings are shown individually.
A40: X example: Grid 3 → Wall 1 + Wall 2; Grid 4 → Wall 3 + Wall 4. Each wall has L=8 m, t=0.45 m, one 2.5 m opening.
...

Sheet Definitions & Use
A1: ← HOME
A3: 1. Number of storeys | B3: Number of above-base storeys included in the building height. Example: 25.
A4: 2. Floor height | B4: Storey-to-storey height in metres. H is calculated automatically.
A5: 4. Soil type / spectrum source | B5: Select A/B/C/D. Ch(T) is interpolated from the separate source worksheets. Static calculations use 'Ch Static' (2025 Static Combined spectra). Modal calculations use 'Ch Modal X' and 'Ch Modal Y' (2025 X Modal Combined spectra / 2025 Modal Y Combined spectra).
A6: 4. Soil type
A7: 5. Grid spacing | B7: Distance between structural grid lines in the considered direction.
A8: 6. Core wall bays | B8: Number of grid bays occupied by the wall length when Manual L is not entered.
A9: 7. Manual L | B9: Optional actual wall length. If entered (>0), it overrides Grid spacing × Core wall bays for that wall.
A10: 8. Opening width / openings | B10: Opening dimensions deducted from the gross wall length when calculating Awi.
A11: 9. Wall thickness t | B11: Wall thickness used to calculate Awi.
A12: 10. Awi | B12: Net wall area used by the NBC wall-area expression: Awi = (Lwi − openings × opening width) × t.
A13: 11. Aw | B13: Aw = Σ[Awi {0.2 + (Lwi/H)²}]. The Lwi/H term is capped at 0.9 in this calculator.
A14: 12. kt | B14: kt = 0.075 / √Aw for a building with shear walls, using the formulation in the supplied workbook.
A15: 13. Empirical T1 | B15: T1 = kt H^0.75.
A16: 14. Amplified empirical T1 | B16: Amplified empirical period = 1.25 × empirical T1, consistent with the workflow in the supplied NBC 105:2025 workbook.
A17: 15. Adopted T1 | B17: If an ETABS/Rayleigh translation period is entered, the calculator uses the lesser of 1.25T1 and that entered period; otherwise it uses 1.25T1.
A18: 16. Ch(T) — Static source | B18: For the ETABS equivalent-static User Coefficient calculation, Ch(T) is obtained by direct linear interpolation from 'Ch Static', which is a numerical copy of the 2025 Static Combined spectra in the supplied workbook.
A19: 17. C(T)
A20: 17. Ch(T) — Modal source | B20: For modal spectrum work, the workbook separately retains the X and Y modal sources. Ch_modal,X(T) is interpolated from 'Ch Modal X'; Ch_modal,Y(T) from 'Ch Modal Y'.
A21: 19. Cs(T)
A22: 20. Cd SLS | B22: Serviceability design coefficient = Cs(T)/Ωs.
A23: 18. C(T) | B23: Elastic site spectrum coefficient = Ch(T) × Z × I.
A24: 19. Cd ULS | B24: Design/base-shear coefficient = C(T)/(Rμ × Ωu).
A25: 20. Cs(T) | B25: Serviceability spectrum coefficient = 0.20 × C(T).
A26: 21. Cd SLS | B26: Serviceability design coefficient = Cs(T)/Ωs.
A27: 22. k exponent | B27: k = 1 for T ≤ 0.5 s; k = 2 for T ≥ 2.5 s; linear interpolation between.
A28: 23. Base shear | B28: V = Cd × W when seismic weight W is supplied.
A29: 24. ETABS synchronization | B29: The ETABS Sync sheet uses the STATIC EQX/EQY C and k values. Modal Ch values are shown separately for reference/modal spectrum work.
A31: Recommended workflow
A32: 1) Select soil and enter storeys/floor height.
A33: 2) Enter X/Y wall geometry, including opening dimensions.
A34: 3) Check Aw, kt and amplified period.
A35: 4) If available, enter ETABS/Rayleigh T1-X and T1-Y.
A36: 5) Confirm adopted T1 and the directly interpolated Ch(T).
A37: 6) Check the resulting EQX/EQY C and k.
A38: 7) Save workbook.
A39: 8) Run the ETABS synchronization GUI while the intended ETABS model is open.
A40: 9) Verify EQX/EQY in Define Load Patterns → Modify Lateral Load.
A41: 10) Run analysis again and verify base shear / story force results.
A44: Engineering verification
...

Sheet Verification
A1: ← HOME
A3: The benchmark values below are taken directly from the original '350 shear wall' and '650 shear wall' sheets. The new equations are independently evaluated with the same Aw and H to verify the period calculation.
A6: Case | B6: H (m) | C6: Original Aw-X | D6: New Aw-X check | E6: Original T-X | F6: New T-X check | G6: Original Aw-Y | H6: New Aw-Y check
A7: 350 shear wall | B7: 90 | C7: 0.68693333 | D7: 0.68693333 | E7: 2.6441485 | F7: 2.6441485 | G7: 0.85866667 | H7: 0.85866667
A8: 650 shear wall | B8: 100 | C8: 2.72448 | D8: 2.72448 | E8: 1.4368765 | F8: 1.4368765 | G8: 2.97216 | H8: 2.97216
A10: PASS/FAIL | B10: =IF(AND(ABS(D7-C7)<0.0000001,ABS(F7-E7)<0.0000001,ABS(H7-G7)<0.0000001,ABS(D8-C8)<0.0000001,ABS(F8-E8)<0.0000001,ABS(H8-G8)<0.0000001),"PASS — Aw and T equations reproduce the original benchmarks","FAIL — investigate")
A12: Finding from comparison | B12: The old workbook's 350/650 wall sheets can be reproduced when the same individual wall layout is entered. The old sheets also contain some geometry inconsistencies (e.g. an 8 m wall length in the 650 X layout while Lwi/H remained 0.08). The new workbook keeps wall geometry explicit instead of hiding such inconsistencies.
A16: Ch(T) source verification | B16: The new workbook has three separate source tables: Ch Static = 2025 Static Combined spectra; Ch Modal X = 2025 X Modal Combined spectra; Ch Modal Y = 2025 Modal Y Combined spectra. The values are copied numerically from the supplied spectrum workbook and interpolated between adjacent T points.
A20: ETABS | B20: The ETABS Sync sheet is intentionally linked to the STATIC EQX/EQY C and k values. Modal Ch values remain separate for modal-spectrum use and are not silently substituted into the ETABS User Coefficient.
A23: Original lateral-load benchmark
A24: Direction | B24: Original T1 (s) | C24: Original Ch(T) | D24: Original C(T) | E24: Original Cd ULS | F24: Original k | G24: New Ch at same T | H24: Status
A25: X | B25: 1.7960957 | C25: 1.3919081 | D25: 0.48716782 | E25: 0.099 | F25: 1.6480478 | G25: =INDEX('Ch Static'!$D$4:$D$12004,MATCH(B25,'Ch Static'!$A$4:$A$12004,1))+(B25-INDEX('Ch Static'!$A$4:$A$12004,MATCH(B25,'Ch Static'!$A$4:$A$12004,1)))*(INDEX('Ch Static'!$D$4:$D$12004,MATCH(B25,'Ch Static'!$A$4:$A$12004,1)+1)-INDEX('Ch Static'!$D$4:$D$12004,MATCH(B25,'Ch Static'!$A$4:$A$12004,1)))/(INDEX('Ch Static'!$A$4:$A$12004,MATCH(B25,'Ch Static'!$A$4:$A$12004,1)+1)-INDEX('Ch Static'!$A$4:$A$12004,MATCH(B25,'Ch Static'!$A$4:$A$12004,1))) | H25: =IF(ABS(G25-C25)<0.000001,"PASS","CHECK")
A26: Y | B26: 1.7196307 | C26: 1.4538006 | D26: 0.5088302 | E26: 0.104 | F26: 1.6098153 | G26: =INDEX('Ch Static'!$D$4:$D$12004,MATCH(B26,'Ch Static'!$A$4:$A$12004,1))+(B26-INDEX('Ch Static'!$A$4:$A$12004,MATCH(B26,'Ch Static'!$A$4:$A$12004,1)))*(INDEX('Ch Static'!$D$4:$D$12004,MATCH(B26,'Ch Static'!$A$4:$A$12004,1)+1)-INDEX('Ch Static'!$D$4:$D$12004,MATCH(B26,'Ch Static'!$A$4:$A$12004,1)))/(INDEX('Ch Static'!$A$4:$A$12004,MATCH(B26,'Ch Static'!$A$4:$A$12004,1)+1)-INDEX('Ch Static'!$A$4:$A$12004,MATCH(B26,'Ch Static'!$A$4:$A$12004,1))) | H26: =IF(ABS(G26-C26)<0.000001,"PASS","CHECK")
A28: Interpretation | B28: The original X/Y lateral-load Ch(T) values are reproduced by the new Static source at the same periods. Therefore the change to a separate direct-interpolation source does not alter the supplied spectrum.
A32: Overall verification conclusion | B32: The comparison must pass only after the Soil A/B/C/D selector is applied to the Ch source columns. Static ETABS C/k use the selected soil's Static spectrum; modal X/Y use their respective selected-soil modal spectra.
A36: Source selector verification | B36: Set X selector to Static or Modal X and Y selector to Static or Modal Y. The displayed Ch(T) and C values change immediately using the corresponding source worksheet.

Sheet ETABS Sync
A1: ETABS EQX / EQY User Coefficient Synchronization
A3: Load Pattern | B3: C | C3: k | D3: Direction | E3: Ecc. Ratio | F3: Top Story | G3: Bottom Story
A4: EQX | B4: ='NBC Calculator'!N17 | C4: ='NBC Calculator'!N20 | D4: X | E4: 0.05 | F4: ="Story"&'NBC Calculator'!B5 | G4: Base
A5: EQY | B5: ='NBC Calculator'!R17 | C5: ='NBC Calculator'!R20 | D5: Y | E5: 0.05 | F5: ="Story"&'NBC Calculator'!B5 | G5: Base
A8: ETABS table to edit: | B8: Load Pattern Definitions - Auto Seismic - User Coefficient
A10: Static ETABS C/k source | B10: NBC Calculator → Static Ch(T) → C(T) → Cd ULS and k
A12: Modal C/k reference | B12: NBC Calculator → Ch Modal X/Y (shown separately; not written by this ETABS User Coefficient sync)
A15: Important | B15: The ETABS model should be open and EQX/EQY should already exist as Seismic → User Coefficient. The GUI does not unlock the model.
A18: ETABS → EXCEL → NBC → ETABS
A19: EQX condition | B19: Ultimate
A20: EQY condition | B20: Ultimate
A22: X DIRECTION
A23: Aw (m²) | B23: 1.9582936
A24: kt | B24: 0.053594763
A25: Empirical T1 (s) | B25: 1.6308539
A26: Amplified T1 (s) | B26: 2.0385674
A27: Adopted T1 (s) | B27: 2.0385674
A28: Ch(T1) | B28: 1.2263514
A29: C(T1) | B29: 0.429223
A30: Cd Ultimate | B30: 0.08759653
A31: Cd Service | B31: 0.071537166
A32: k exponent | B32: 1.7692837
A34: Y DIRECTION
A35: Aw (m²) | B35: 2.2030803
A36: kt | B36: 0.050529628
A37: Empirical T1 (s) | B37: 1.5375838
A38: Amplified T1 (s) | B38: 1.9219798
A39: Adopted T1 (s) | B39: 1.9219798
A40: Ch(T1) | B40: 1.3007421
A41: C(T1) | B41: 0.45525973
A42: Cd Ultimate | B42: 0.09291015
A43: Cd Service | B43: 0.075876622
A44: k exponent | B44: 1.7109899

Sheet NBC Parameters
A1: ← HOME
A3: Soil | B3: Ta (s) | C3: Tc (s) | D3: α | E3: Td (s) | F3: K | G3: Ta Modal (s) | H3: Note
A4: A | B4: 0 | C4: 0.5 | D4: 2.5 | E4: 4 | F4: 0.2 | G4: 0.1 | H4: Reference values from supplied workbook
A5: B | B5: 0 | C5: 0.7 | D5: 2.5 | E5: 4 | F5: 0.2 | G5: 0.1 | H5: Reference values from supplied workbook
A6: C | B6: 0 | C6: 1 | D6: 2.5 | E6: 4 | F6: 0.2 | G6: 0.1 | H6: Reference values from supplied workbook
A7: D | B7: 0 | C7: 2 | D7: 2.25 | E7: 5 | F7: 0.2 | G7: 0.5 | H7: Reference values from supplied workbook
A10: Note | B10: Ch(T) itself is NOT calculated from these parameters in the main calculator. It is directly linearly interpolated from the copied Ch Spectrum worksheet.
A14: NBC 105:2025 Table 5-2 — Ductility and Overstrength Factors
A15: Structural System | B15: Rμ | C15: Ωu | D15: Ωs
A16: Steel Moment Resisting Frame | B16: 4 | C16: 1.5 | D16: 1.25
A17: Reinforced Concrete Moment Resisting Frame | B17: 4 | C17: 1.5 | D17: 1.25
A18: Steel + RC Composite Moment Resisting Frame | B18: 4 | C18: 1.5 | D18: 1.25
A19: Steel Eccentrically Braced Frame | B19: 4 | C19: 1.5 | D19: 1.25
A20: Steel + RC Composite Eccentrically Braced Frame | B20: 4 | C20: 1.5 | D20: 1.25
A21: Steel Concentric Braced Frame | B21: 3 | C21: 1.3 | D21: 1.15
A22: Steel + RC Composite Concentric Braced Frame | B22: 3 | C22: 1.3 | D22: 1.15
A23: Steel Buckling Restraint Braces | B23: 4 | C23: 1.5 | D23: 1.25
A24: RC Shear wall | B24: 3 | C24: 1.3 | D24: 1.15
A25: Steel + RC Composite Shear Wall | B25: 3 | C25: 1.3 | D25: 1.15
A26: Reinforced Masonry Shear wall | B26: 2.5 | C26: 1.2 | D26: 1.1
A27: Confined Masonry wall | B27: 2.5 | C27: 1.2 | D27: 1.1
... A36: Reinforced Masonry Shear wall — Dual System | B36: 2.5 | C36: 1.2 | D36: 1.1

Sheet Ch Static
A1: ← HOME
A3: T (s) | B3: Soil A | C3: Soil B | D3: Soil C | E3: Soil D | F3: Source | H3: Interpolation | I3: Linear interpolation between adjacent supplied T points
A4: 0 | B4: 2.5 | C4: 2.5 | D4: 2.5 | E4: 2.25 | F4: 2025 Static Combined spectra | H4: Range | I4: 0.0 to 5.999999999999446 s
A5: 0.0005 | B5: 2.5 | C5: 2.5 | D5: 2.5 | E5: 2.25 | F5: 2025 Static Combined spectra | H5: Number of points | I5: 12001
A6: 0.001 | B6: 2.5 | C6: 2.5 | D6: 2.5 | E6: 2.25 | F6: 2025 Static Combined spectra
A7: 0.0015 | B7: 2.5 | C7: 2.5 | D7: 2.5 | E7: 2.25 | F7: 2025 Static Combined spectra
A8: 0.002 | B8: 2.5 | C8: 2.5 | D8: 2.5 | E8: 2.25 | F8: 2025 Static Combined spectra
A9: 0.0025 | B9: 2.5 | C9: 2.5 | D9: 2.5 | E9: 2.25 | F9: 2025 Static Combined spectra
A10: 0.003 | B10: 2.5 | C10: 2.5 | D10: 2.5 | E10: 2.25 | F10: 2025 Static Combined spectra
A11: 0.0035 | B11: 2.5 | C11: 2.5 | D11: 2.5 | E11: 2.25 | F11: 2025 Static Combined spectra
A12: 0.004 | B12: 2.5 | C12: 2.5 | D12: 2.5 | E12: 2.25 | F12: 2025 Static Combined spectra
A13: 0.0045 | B13: 2.5 | C13: 2.5 | D13: 2.5 | E13: 2.25 | F13: 2025 Static Combined spectra
A14: 0.005 | B14: 2.5 | C14: 2.5 | D14: 2.5 | E14: 2.25 | F14: 2025 Static Combined spectra
A15: 0.0055 | B15: 2.5 | C15: 2.5 | D15: 2.5 | E15: 2.25 | F15: 2025 Static Combined spectra
A16: 0.006 | B16: 2.5 | C16: 2.5 | D16: 2.5 | E16: 2.25 | F16: 2025 Static Combined spectra
A17: 0.0065 | B17: 2.5 | C17: 2.5 | D17: 2.5 | E17: 2.25 | F17: 2025 Static Combined spectra
... A12004: 6 | B12004: 0.13888889 | C12004: 0.19444444 | D12004: 0.27777778 | E12004: 0.625 | F12004: 2025 Static Combined spectra

Sheet Ch Modal X
A1: ← HOME
A3: T (s) | B3: Soil A | C3: Soil B | D3: Soil C | E3: Soil D | F3: Source | H3: Interpolation | I3: Linear interpolation between adjacent supplied T points
A4: 0 | B4: 1 | C4: 1 | D4: 1 | E4: 1 | F4: 2025 X Modal Combined spectra | H4: Range | I4: 0.0 to 5.999999999999446 s
A5: 0.0005 | B5: 1.0075 | C5: 1.0075 | D5: 1.0075 | E5: 1.00125 | F5: 2025 X Modal Combined spectra | H5: Number of points | I5: 12001
A6: 0.001 | B6: 1.015 | C6: 1.015 | D6: 1.015 | E6: 1.0025 | F6: 2025 X Modal Combined spectra
A7: 0.0015 | B7: 1.0225 | C7: 1.0225 | D7: 1.0225 | E7: 1.00375 | F7: 2025 X Modal Combined spectra
A8: 0.002 | B8: 1.03 | C8: 1.03 | D8: 1.03 | E8: 1.005 | F8: 2025 X Modal Combined spectra
A9: 0.0025 | B9: 1.0375 | C9: 1.0375 | D9: 1.0375 | E9: 1.00625 | F9: 2025 X Modal Combined spectra
A10: 0.003 | B10: 1.045 | C10: 1.045 | D10: 1.045 | E10: 1.0075 | F10: 2025 X Modal Combined spectra
A11: 0.0035 | B11: 1.0525 | C11: 1.0525 | D11: 1.0525 | E11: 1.00875 | F11: 2025 X Modal Combined spectra
A12: 0.004 | B12: 1.06 | C12: 1.06 | D12: 1.06 | E12: 1.01 | F12: 2025 X Modal Combined spectra
A13: 0.0045 | B13: 1.0675 | C13: 1.0675 | D13: 1.0675 | E13: 1.01125 | F13: 2025 X Modal Combined spectra
A14: 0.005 | B14: 1.075 | C14: 1.075 | D14: 1.075 | E14: 1.0125 | F14: 2025 X Modal Combined spectra
A15: 0.0055 | B15: 1.0825 | C15: 1.0825 | D15: 1.0825 | E15: 1.01375 | F15: 2025 X Modal Combined spectra
A16: 0.006 | B16: 1.09 | C16: 1.09 | D16: 1.09 | E16: 1.015 | F16: 2025 X Modal Combined spectra
A17: 0.0065 | B17: 1.0975 | C17: 1.0975 | D17: 1.0975 | E17: 1.01625 | F17: 2025 X Modal Combined spectra
... A12004: 6 | B12004: 0.13888889 | C12004: 0.19444444 | D12004: 0.27777778 | E12004: 0.625 | F12004: 2025 X Modal Combined spectra

Sheet Ch Modal Y
A1: ← HOME
A3: T (s) | B3: Soil A | C3: Soil B | D3: Soil C | E3: Soil D | F3: Source | H3: Interpolation | I3: Linear interpolation between adjacent supplied T points
A4: 0 | B4: 1 | C4: 1 | D4: 1 | E4: 1 | F4: 2025 Modal Y Combined spectra | H4: Range | I4: 0.0 to 5.999999999999446 s
A5: 0.0005 | B5: 1.0075 | C5: 1.0075 | D5: 1.0075 | E5: 1.00125 | F5: 2025 Modal Y Combined spectra | H5: Number of points | I5: 12001
A6: 0.001 | B6: 1.015 | C6: 1.015 | D6: 1.015 | E6: 1.0025 | F6: 2025 Modal Y Combined spectra
A7: 0.0015 | B7: 1.0225 | C7: 1.0225 | D7: 1.0225 | E7: 1.00375 | F7: 2025 Modal Y Combined spectra
A8: 0.002 | B8: 1.03 | C8: 1.03 | D8: 1.03 | E8: 1.005 | F8: 2025 Modal Y Combined spectra
A9: 0.0025 | B9: 1.0375 | C9: 1.0375 | D9: 1.0375 | E9: 1.00625 | F9: 2025 Modal Y Combined spectra
A10: 0.003 | B10: 1.045 | C10: 1.045 | D10: 1.045 | E10: 1.0075 | F10: 2025 Modal Y Combined spectra
A11: 0.0035 | B11: 1.0525 | C11: 1.0525 | D11: 1.0525 | E11: 1.00875 | F11: 2025 Modal Y Combined spectra
A12: 0.004 | B12: 1.06 | C12: 1.06 | D12: 1.06 | E12: 1.01 | F12: 2025 Modal Y Combined spectra
A13: 0.0045 | B13: 1.0675 | C13: 1.0675 | D13: 1.0675 | E13: 1.01125 | F13: 2025 Modal Y Combined spectra
A14: 0.005 | B14: 1.075 | C14: 1.075 | D14: 1.075 | E14: 1.0125 | F14: 2025 Modal Y Combined spectra
A15: 0.0055 | B15: 1.0825 | C15: 1.0825 | D15: 1.0825 | E15: 1.01375 | F15: 2025 Modal Y Combined spectra
A16: 0.006 | B16: 1.09 | C16: 1.09 | D16: 1.09 | E16: 1.015 | F16: 2025 Modal Y Combined spectra
A17: 0.0065 | B17: 1.0975 | C17: 1.0975 | D17: 1.0975 | E17: 1.01625 | F17: 2025 Modal Y Combined spectra
... A12004: 6 | B12004: 0.13888889 | C12004: 0.19444444 | D12004: 0.27777778 | E12004: 0.625 | F12004: 2025 Modal Y Combined spectra

Sheet ETABS_ULTIMATE_LOAD_NEPAL_3_BEL
A1: ETABS INPUT / INTEGRATION SUMMARY
A3: Source EDB | B3: D:\Thesis\Etabs\NBC Ultimate\Ultimate Belt truss, outrigger and cap truss 6 m\ULTIMATE LOAD - NEPAL - 3 - BELT TRUSS, OUTRIGGER CAP TRUSS.EDB
A4: Condition | B4: Ultimate
A5: Storeys | B5: 25
A6: X Grid Spacing (m) | B6: 0
A7: Y Grid Spacing (m) | B7: 0
A8: X Records | B8: 4
A9: Y Records | B9: 3
A11: Direction | B11: Record | C11: Grid | D11: Pier | E11: Length (mm) | F11: Thickness (mm) | G11: Opening W (mm) | H11: No. Openings
A12: X | B12: 1 | D12: P1 | E12: 6000 | F12: 600 | G12: 0 | H12: 0
A13: X | B13: 2 | D13: P1 | E13: 6000 | F13: 600 | G13: 0 | H13: 0
A14: X | B14: 3 | D14: P3 | E14: 6000 | F14: 600 | G14: 0 | H14: 0
A15: X | B15: 4 | D15: P3 | E15: 6000 | F15: 600 | G15: 0 | H15: 0
A16: Y | B16: 1 | D16: P1 | E16: 6000 | F16: 600 | G16: 0 | H16: 0
A17: Y | B17: 2 | D17: P2 | E17: 6000 | F17: 600 | G17: 0 | H17: 0
A18: Y | B18: 3 | D18: P3 | E18: 6000 | F18: 600 | G18: 0 | H18: 0
